2025-07-20 12:12:18 - __main__ - INFO - ==== INICIO ====
2025-07-20 12:12:20 - __main__ - INFO - Generando 10 temas con gemma3...
2025-07-20 12:12:23 - __main__ - ERROR - Error de conexi√≥n: 500 Server Error: Internal Server Error for url: http://localhost:11434/api/generate
2025-07-20 12:12:23 - __main__ - ERROR - Soluciones posibles:
2025-07-20 12:12:23 - __main__ - ERROR - 1. Ejecuta 'ollama serve' en otra terminal
2025-07-20 12:12:23 - __main__ - ERROR - 2. Verifica que el modelo 'gemma3' est√© descargado (ollama pull gemma3)
2025-07-20 12:12:23 - __main__ - WARNING - No se generaron temas. Verifica logs anteriores.
2025-07-20 12:12:23 - __main__ - INFO - ==== FINALIZADO ====
2025-07-20 12:43:20 - __main__ - INFO - ==== INICIO ====
2025-07-20 12:43:22 - __main__ - INFO - Generando 10 temas con gemma3...
2025-07-20 12:43:53 - __main__ - INFO - ‚úÖ 10 temas generados
2025-07-20 12:43:53 - __main__ - INFO - üìÑ Temas guardados en C:\Users\lugod\auto_blog_ia\temas\temas.txt
2025-07-20 12:43:53 - __main__ - INFO - ==== FINALIZADO ====
2025-07-22 16:47:33 - __main__ - INFO - ==== INICIO ====
2025-07-22 16:47:33 - __main__ - INFO - Generando 10 temas con IA en la nube...
2025-07-22 16:47:33 - __main__ - ERROR - Error de conexi√≥n con el servicio de IA: 404 Client Error: Not Found for url: https://api-inference.huggingface.co/models/mistralai/Mistral-7B-Instruct-v0.1
2025-07-22 16:47:33 - __main__ - WARNING - No se generaron temas. Verifica logs anteriores.
2025-07-22 16:47:33 - __main__ - INFO - ==== FINALIZADO ====
2025-07-22 16:48:49 - __main__ - INFO - ==== INICIO ====
2025-07-22 16:48:49 - __main__ - INFO - Generando 10 temas con IA en la nube...
2025-07-22 16:48:49 - __main__ - ERROR - Error de conexi√≥n con el servicio de IA: 404 Client Error: Not Found for url: https://api-inference.huggingface.co/models/mistralai/Mistral-7B-v0.1
2025-07-22 16:48:49 - __main__ - WARNING - No se generaron temas. Verifica logs anteriores.
2025-07-22 16:48:49 - __main__ - INFO - ==== FINALIZADO ====
2025-07-22 16:54:15 - __main__ - INFO - ==== INICIO ====
2025-07-22 16:54:15 - __main__ - INFO - Generando 10 temas con IA en la nube...
2025-07-22 16:54:16 - __main__ - ERROR - Error de conexi√≥n con el servicio de IA: 404 Client Error: Not Found for url: https://api-inference.huggingface.co/models/gpt2
2025-07-22 16:54:16 - __main__ - WARNING - No se generaron temas. Verifica logs anteriores.
2025-07-22 16:54:16 - __main__ - INFO - ==== FINALIZADO ====
2025-07-22 16:59:30 - __main__ - INFO - ==== INICIO ====
2025-07-22 16:59:30 - __main__ - INFO - Generando 10 temas...
2025-07-22 16:59:30 - __main__ - ERROR - Error HTTP 404: 404 Client Error: Not Found for url: https://api-inference.huggingface.co/models/mistralai/Mistral-7B-v0.1
2025-07-22 16:59:30 - __main__ - ERROR - No se recibi√≥ respuesta del modelo
2025-07-22 16:59:30 - __main__ - ERROR - ‚ö†Ô∏è No se generaron temas. Revisa logs.
2025-07-22 16:59:30 - __main__ - INFO - ==== FINALIZADO ====
2025-07-23 22:11:30 - __main__ - INFO - ==== INICIO ====
2025-07-23 22:11:30 - __main__ - INFO - Generando 10 temas con Mistral 7B...
2025-07-23 22:11:30 - __main__ - ERROR - Error inesperado: name 'DEEPINFRA_KEY' is not defined
Traceback (most recent call last):
  File "C:\Users\lugod\auto_blog_ia_nube\temas\generacion_temas.py", line 53, in generar_con_ia
    "Authorization": f"Bearer {DEEPINFRA_KEY}",
                               ^^^^^^^^^^^^^
NameError: name 'DEEPINFRA_KEY' is not defined. Did you mean: 'DEEPINFRA_API'?
2025-07-23 22:11:30 - __main__ - ERROR - No se recibi√≥ respuesta del modelo
2025-07-23 22:11:30 - __main__ - ERROR - ‚ö†Ô∏è No se generaron temas. Revisa logs.
2025-07-23 22:11:30 - __main__ - INFO - ==== FINALIZADO ====
2025-07-23 22:15:06 - __main__ - INFO - ==== INICIO ====
2025-07-23 22:15:06 - __main__ - INFO - Generando 10 temas con Mistral 7B...
2025-07-23 22:15:06 - __main__ - ERROR - Error inesperado: name 'DEEPINFRA_KEY' is not defined
Traceback (most recent call last):
  File "C:\Users\lugod\auto_blog_ia_nube\temas\generacion_temas.py", line 54, in generar_con_ia
    "Authorization": f"Bearer {DEEPINFRA_KEY}",
                               ^^^^^^^^^^^^^
NameError: name 'DEEPINFRA_KEY' is not defined. Did you mean: 'DEEPINFRA_API'?
2025-07-23 22:15:06 - __main__ - ERROR - No se recibi√≥ respuesta del modelo
2025-07-23 22:15:06 - __main__ - ERROR - ‚ö†Ô∏è No se generaron temas. Revisa logs.
2025-07-23 22:15:06 - __main__ - INFO - ==== FINALIZADO ====
2025-07-23 22:17:07 - __main__ - INFO - ==== INICIO ====
2025-07-23 22:17:07 - __main__ - INFO - Generando 10 temas con Mistral 7B...
2025-07-23 22:17:08 - __main__ - ERROR - Error de conexi√≥n: 402 Client Error: Payment Required for url: https://api.deepinfra.com/v1/inference/mistralai/Mistral-7B-Instruct-v0.1
2025-07-23 22:17:08 - __main__ - ERROR - No se recibi√≥ respuesta del modelo
2025-07-23 22:17:08 - __main__ - ERROR - ‚ö†Ô∏è No se generaron temas. Revisa logs.
2025-07-23 22:17:08 - __main__ - INFO - ==== FINALIZADO ====
2025-07-23 22:28:10 - __main__ - INFO - ==== INICIO ====
2025-07-23 22:28:10 - __main__ - INFO - Generando 10 temas con gpt-4o-mini...
2025-07-23 22:28:15 - httpx - INFO - HTTP Request: POST https://api.openai.com/v1/chat/completions "HTTP/1.1 200 OK"
2025-07-23 22:28:15 - __main__ - INFO - üìÑ 10 temas guardados en C:\Users\lugod\auto_blog_ia_nube\temas\temas.txt
2025-07-23 22:28:15 - __main__ - INFO - ==== FINALIZADO ====
2025-07-23 22:43:14 - __main__ - INFO - ==== INICIO ====
2025-07-23 22:43:14 - __main__ - INFO - Generando 10 temas con gpt-4.5-preview...
2025-07-23 22:43:16 - httpx - INFO - HTTP Request: POST https://api.openai.com/v1/chat/completions "HTTP/1.1 404 Not Found"
2025-07-23 22:43:16 - __main__ - ERROR - Error inesperado: Error code: 404 - {'error': {'message': 'The model `gpt-4.5-preview` does not exist or you do not have access to it.', 'type': 'invalid_request_error', 'param': None, 'code': 'model_not_found'}}
Traceback (most recent call last):
  File "C:\Users\lugod\auto_blog_ia_nube\temas\generacion_temas.py", line 54, in generar_con_ia
    response = client.chat.completions.create(
        model=MODELO,
    ...<11 lines>...
        temperature=TEMPERATURE
    )
  File "C:\Users\lugod\AppData\Local\Programs\Python\Python313\Lib\site-packages\openai\_utils\_utils.py", line 287, in wrapper
    return func(*args, **kwargs)
  File "C:\Users\lugod\AppData\Local\Programs\Python\Python313\Lib\site-packages\openai\resources\chat\completions\completions.py", line 925, in create
    return self._post(
           ~~~~~~~~~~^
        "/chat/completions",
        ^^^^^^^^^^^^^^^^^^^^
    ...<43 lines>...
        stream_cls=Stream[ChatCompletionChunk],
        ^^^^^^^^^^^^^^^^^^^^^^^^^^^^^^^^^^^^^^^
    )
    ^
  File "C:\Users\lugod\AppData\Local\Programs\Python\Python313\Lib\site-packages\openai\_base_client.py", line 1239, in post
    return cast(ResponseT, self.request(cast_to, opts, stream=stream, stream_cls=stream_cls))
                           ~~~~~~~~~~~~^^^^^^^^^^^^^^^^^^^^^^^^^^^^^^^^^^^^^^^^^^^^^^^^^^^^^
  File "C:\Users\lugod\AppData\Local\Programs\Python\Python313\Lib\site-packages\openai\_base_client.py", line 1034, in request
    raise self._make_status_error_from_response(err.response) from None
openai.NotFoundError: Error code: 404 - {'error': {'message': 'The model `gpt-4.5-preview` does not exist or you do not have access to it.', 'type': 'invalid_request_error', 'param': None, 'code': 'model_not_found'}}
2025-07-23 22:43:16 - __main__ - ERROR - No se generaron temas
2025-07-23 22:43:16 - __main__ - INFO - ==== FINALIZADO ====
2025-07-23 22:46:51 - __main__ - INFO - ==== INICIO ====
2025-07-23 22:46:51 - __main__ - INFO - Generando 10 temas avanzados con gpt-4.5-preview...
2025-07-23 22:46:53 - httpx - INFO - HTTP Request: POST https://api.openai.com/v1/chat/completions "HTTP/1.1 404 Not Found"
2025-07-23 22:46:53 - __main__ - ERROR - Error inesperado: Error code: 404 - {'error': {'message': 'The model `gpt-4.5-preview` does not exist or you do not have access to it.', 'type': 'invalid_request_error', 'param': None, 'code': 'model_not_found'}}
Traceback (most recent call last):
  File "C:\Users\lugod\auto_blog_ia_nube\temas\generacion_temas.py", line 54, in generar_con_ia
    response = client.chat.completions.create(
        model=MODELO,
    ...<12 lines>...
        top_p=0.9  # Par√°metro adicional para mejor calidad
    )
  File "C:\Users\lugod\AppData\Local\Programs\Python\Python313\Lib\site-packages\openai\_utils\_utils.py", line 287, in wrapper
    return func(*args, **kwargs)
  File "C:\Users\lugod\AppData\Local\Programs\Python\Python313\Lib\site-packages\openai\resources\chat\completions\completions.py", line 925, in create
    return self._post(
           ~~~~~~~~~~^
        "/chat/completions",
        ^^^^^^^^^^^^^^^^^^^^
    ...<43 lines>...
        stream_cls=Stream[ChatCompletionChunk],
        ^^^^^^^^^^^^^^^^^^^^^^^^^^^^^^^^^^^^^^^
    )
    ^
  File "C:\Users\lugod\AppData\Local\Programs\Python\Python313\Lib\site-packages\openai\_base_client.py", line 1239, in post
    return cast(ResponseT, self.request(cast_to, opts, stream=stream, stream_cls=stream_cls))
                           ~~~~~~~~~~~~^^^^^^^^^^^^^^^^^^^^^^^^^^^^^^^^^^^^^^^^^^^^^^^^^^^^^
  File "C:\Users\lugod\AppData\Local\Programs\Python\Python313\Lib\site-packages\openai\_base_client.py", line 1034, in request
    raise self._make_status_error_from_response(err.response) from None
openai.NotFoundError: Error code: 404 - {'error': {'message': 'The model `gpt-4.5-preview` does not exist or you do not have access to it.', 'type': 'invalid_request_error', 'param': None, 'code': 'model_not_found'}}
2025-07-23 22:46:53 - __main__ - ERROR - ‚ö†Ô∏è No se generaron temas. Verifica los logs.
2025-07-23 22:46:53 - __main__ - INFO - ==== FINALIZADO ====
